var exc = Exception.new("exc");
[00000001] Exception `exc'
throw exc;
[00000002:error] !!! input.u:3.1-9: exc
try {
  echo ("before");
  throw exc;
  echo ("after");
} catch (var e if e.isA(exc)) {
  echo ("caught");
};
[00000003] *** before
[00000004] *** caught
try {
  echo ("before");
  throw exc;
  echo ("after");
} catch (var e) {
  echo ("caught");
};
[00000005] *** before
[00000006] *** caught
try {
  try {
    echo ("before");
    throw exc;
    echo ("after");
  } catch (var f if f.isA(Float)) {
    echo ("bad catch");
  }
} catch (var e if e.isA(Float)) {
  echo ("bad catch");
} catch (var e if e.isA(exc)) {
  echo ("caught");
} catch (var e) {
  echo ("bad catch");
};
[00000007] *** before
[00000008] *** caught
try {
  try {
    echo ("before");
    throw exc;
    echo ("after");
  } catch (var e if e.isA(exc)) {
    echo ("caught");
    throw e;
  }
} catch (var e if e.isA(Float)) {
  echo ("bad catch");
} catch (var e if e.isA(exc)) {
  echo ("recaught");
} catch (var e) {
  echo ("bad catch");
};
[00000009] *** before
[00000010] *** caught
[00000011] *** recaught
try {
  try {
    echo ("before");
    throw exc;
    echo ("after");
  } catch (var exc) {
    echo ("caught");
    throw;
  }
} catch (var e if e.isA(Float)) {
  echo ("bad catch");
} catch (var e if e.isA(exc)) {
  echo ("recaught");
} catch (var e) {
  echo ("bad catch");
};
[00000012] *** before
[00000013] *** caught
[00000014] *** recaught


// We used to stay stuck in the following case, because the
// Exception.Type was buggy, and its instantiation created new
// exceptions.  The problem was that a slot was used to store the
// guilty expression, and in the case of a primitive (where a float
// was expected) resulted in the primitive being fired, because of the
// lack of a getSlot.
0 + 0.getSlot("+");
[00000015:error] !!! input.u:86.1-18: +: unexpected Primitive_0xADDR for argument 1, expected a Float
